
2019-09-27 16:52:11,330 - application - ERROR - Exception on /metrics [GET]
Traceback (most recent call last):
  File "/usr/local/opt/python@2/Frameworks/Python.framework/Versions/2.7/lib/python2.7/site-packages/flask/app.py", line 2446, in wsgi_app
    response = self.full_dispatch_request()
  File "/usr/local/opt/python@2/Frameworks/Python.framework/Versions/2.7/lib/python2.7/site-packages/flask/app.py", line 1951, in full_dispatch_request
    rv = self.handle_user_exception(e)
  File "/usr/local/opt/python@2/Frameworks/Python.framework/Versions/2.7/lib/python2.7/site-packages/flask/app.py", line 1820, in handle_user_exception
    reraise(exc_type, exc_value, tb)
  File "/usr/local/opt/python@2/Frameworks/Python.framework/Versions/2.7/lib/python2.7/site-packages/flask/app.py", line 1949, in full_dispatch_request
    rv = self.dispatch_request()
  File "/usr/local/opt/python@2/Frameworks/Python.framework/Versions/2.7/lib/python2.7/site-packages/flask/app.py", line 1935, in dispatch_request
    return self.view_functions[rule.endpoint](**req.view_args)
  File "./application/views.py", line 12, in metrics
    _value = main.get_metrics(application.config['CB_DATABASE'], application.config['CB_USERNAME'], application.config['CB_PASSWORD'])
  File "./application/main.py", line 835, in get_metrics
    clusterValues = _getCluster(url, user, passwrd)
  File "./application/main.py", line 41, in _getCluster
    f = (urllib2.urlopen(req)).read()
  File "/usr/local/opt/python@2/Frameworks/Python.framework/Versions/2.7/lib/python2.7/urllib2.py", line 154, in urlopen
    return opener.open(url, data, timeout)
  File "/usr/local/opt/python@2/Frameworks/Python.framework/Versions/2.7/lib/python2.7/urllib2.py", line 429, in open
    response = self._open(req, data)
  File "/usr/local/opt/python@2/Frameworks/Python.framework/Versions/2.7/lib/python2.7/urllib2.py", line 447, in _open
    '_open', req)
  File "/usr/local/opt/python@2/Frameworks/Python.framework/Versions/2.7/lib/python2.7/urllib2.py", line 407, in _call_chain
    result = func(*args)
  File "/usr/local/opt/python@2/Frameworks/Python.framework/Versions/2.7/lib/python2.7/urllib2.py", line 1228, in http_open
    return self.do_open(httplib.HTTPConnection, req)
  File "/usr/local/opt/python@2/Frameworks/Python.framework/Versions/2.7/lib/python2.7/urllib2.py", line 1198, in do_open
    raise URLError(err)
URLError: <urlopen error [Errno 61] Connection refused>
2019-09-27 16:52:11,333 - application - ERROR - Server Error: 500 Internal Server Error: The server encountered an internal error and was unable to complete your request. Either the server is overloaded or there is an error in the application.
2019-09-27 16:53:41,333 - application - ERROR - Exception on /metrics [GET]
Traceback (most recent call last):
  File "/usr/local/opt/python@2/Frameworks/Python.framework/Versions/2.7/lib/python2.7/site-packages/flask/app.py", line 2446, in wsgi_app
    response = self.full_dispatch_request()
  File "/usr/local/opt/python@2/Frameworks/Python.framework/Versions/2.7/lib/python2.7/site-packages/flask/app.py", line 1951, in full_dispatch_request
    rv = self.handle_user_exception(e)
  File "/usr/local/opt/python@2/Frameworks/Python.framework/Versions/2.7/lib/python2.7/site-packages/flask/app.py", line 1820, in handle_user_exception
    reraise(exc_type, exc_value, tb)
  File "/usr/local/opt/python@2/Frameworks/Python.framework/Versions/2.7/lib/python2.7/site-packages/flask/app.py", line 1949, in full_dispatch_request
    rv = self.dispatch_request()
  File "/usr/local/opt/python@2/Frameworks/Python.framework/Versions/2.7/lib/python2.7/site-packages/flask/app.py", line 1935, in dispatch_request
    return self.view_functions[rule.endpoint](**req.view_args)
  File "./application/views.py", line 12, in metrics
    _value = main.get_metrics(application.config['CB_DATABASE'], application.config['CB_USERNAME'], application.config['CB_PASSWORD'])
  File "./application/main.py", line 835, in get_metrics
    clusterValues = _getCluster(url, user, passwrd)
  File "./application/main.py", line 41, in _getCluster
    f = (urllib2.urlopen(req)).read()
  File "/usr/local/opt/python@2/Frameworks/Python.framework/Versions/2.7/lib/python2.7/urllib2.py", line 154, in urlopen
    return opener.open(url, data, timeout)
  File "/usr/local/opt/python@2/Frameworks/Python.framework/Versions/2.7/lib/python2.7/urllib2.py", line 429, in open
    response = self._open(req, data)
  File "/usr/local/opt/python@2/Frameworks/Python.framework/Versions/2.7/lib/python2.7/urllib2.py", line 447, in _open
    '_open', req)
  File "/usr/local/opt/python@2/Frameworks/Python.framework/Versions/2.7/lib/python2.7/urllib2.py", line 407, in _call_chain
    result = func(*args)
  File "/usr/local/opt/python@2/Frameworks/Python.framework/Versions/2.7/lib/python2.7/urllib2.py", line 1228, in http_open
    return self.do_open(httplib.HTTPConnection, req)
  File "/usr/local/opt/python@2/Frameworks/Python.framework/Versions/2.7/lib/python2.7/urllib2.py", line 1198, in do_open
    raise URLError(err)
URLError: <urlopen error [Errno 61] Connection refused>
2019-09-27 16:53:41,336 - application - ERROR - Server Error: 500 Internal Server Error: The server encountered an internal error and was unable to complete your request. Either the server is overloaded or there is an error in the application.
2019-09-27 16:53:56,321 - application - ERROR - Exception on /metrics [GET]
Traceback (most recent call last):
  File "/usr/local/opt/python@2/Frameworks/Python.framework/Versions/2.7/lib/python2.7/site-packages/flask/app.py", line 2446, in wsgi_app
    response = self.full_dispatch_request()
  File "/usr/local/opt/python@2/Frameworks/Python.framework/Versions/2.7/lib/python2.7/site-packages/flask/app.py", line 1951, in full_dispatch_request
    rv = self.handle_user_exception(e)
  File "/usr/local/opt/python@2/Frameworks/Python.framework/Versions/2.7/lib/python2.7/site-packages/flask/app.py", line 1820, in handle_user_exception
    reraise(exc_type, exc_value, tb)
  File "/usr/local/opt/python@2/Frameworks/Python.framework/Versions/2.7/lib/python2.7/site-packages/flask/app.py", line 1949, in full_dispatch_request
    rv = self.dispatch_request()
  File "/usr/local/opt/python@2/Frameworks/Python.framework/Versions/2.7/lib/python2.7/site-packages/flask/app.py", line 1935, in dispatch_request
    return self.view_functions[rule.endpoint](**req.view_args)
  File "./application/views.py", line 12, in metrics
    _value = main.get_metrics(application.config['CB_DATABASE'], application.config['CB_USERNAME'], application.config['CB_PASSWORD'])
  File "./application/main.py", line 835, in get_metrics
    clusterValues = _getCluster(url, user, passwrd)
  File "./application/main.py", line 41, in _getCluster
    f = (urllib2.urlopen(req)).read()
  File "/usr/local/opt/python@2/Frameworks/Python.framework/Versions/2.7/lib/python2.7/urllib2.py", line 154, in urlopen
    return opener.open(url, data, timeout)
  File "/usr/local/opt/python@2/Frameworks/Python.framework/Versions/2.7/lib/python2.7/urllib2.py", line 429, in open
    response = self._open(req, data)
  File "/usr/local/opt/python@2/Frameworks/Python.framework/Versions/2.7/lib/python2.7/urllib2.py", line 447, in _open
    '_open', req)
  File "/usr/local/opt/python@2/Frameworks/Python.framework/Versions/2.7/lib/python2.7/urllib2.py", line 407, in _call_chain
    result = func(*args)
  File "/usr/local/opt/python@2/Frameworks/Python.framework/Versions/2.7/lib/python2.7/urllib2.py", line 1228, in http_open
    return self.do_open(httplib.HTTPConnection, req)
  File "/usr/local/opt/python@2/Frameworks/Python.framework/Versions/2.7/lib/python2.7/urllib2.py", line 1198, in do_open
    raise URLError(err)
URLError: <urlopen error [Errno 61] Connection refused>
2019-09-27 16:53:56,323 - application - ERROR - Server Error: 500 Internal Server Error: The server encountered an internal error and was unable to complete your request. Either the server is overloaded or there is an error in the application.
